## 11장 예외와 에러처리



### 예외와 에러

- 에러 : 컴파일 시 문법적인 오류와 런타임 시 널포인트 참조와 같은 오류로 프로세스에 심각한 문제를 야기 시켜 프로세스를 종료 시킬 수 있는 것.

- 예외: 컴퓨터 시스템의 동작 도중 예기치 않았던 이상 상태가 발생하여 수행 중인 프로그램이 영향을 받는 것. 즉, 예상치 못한 에러이다.
- 예외 처리 : 에러를 컨트롤하는 매커니즘



### Error 객체

- 에러를 생성할 수 있는 자바스크립트 내장 객체
- `message` : 사람이 읽을 수 있는 오류에 대한 설명 (선택)
- `fileName` : 생성할 `Error` 객체의 `fileName` 속성 값 (선택). 기본값은 `Error` 생성자를 호출한 코드를 포함하고 있는 파일의 이름.
- `lineNumber` : 생성할 `Error` 객체의 `lineNumber` 속성 값 (선택). 기본값은 `Error` 생성자 호출을 포함한 줄 번호.

```javascript
new Error([message[, fileName[, lineNumber]]]);
```

- 속성값은 대표적으로 `Error.prototype` 의 속성값인  `message`, `name`, `stack` 이 있다 .





### 에러 유형

- JavaScript에는 일반적인 `Error` 생성자 외에도 7개의 중요 에러 생성자가 존재.

  - [`EvalError`](https://developer.mozilla.org/ko/docs/Web/JavaScript/Reference/Global_Objects/EvalError) : 전역 함수 `eval()` 오류의 인스턴스를 생성한다.

  - [`InternalError`](https://developer.mozilla.org/ko/docs/Web/JavaScript/Reference/Global_Objects/InternalError) : JavaScript 엔진의 내부에서 오류가 발생했음을 나타내는 오류 인스턴스를 생성한다.
  - [`RangeError`](https://developer.mozilla.org/ko/docs/Web/JavaScript/Reference/Global_Objects/RangeError) : 숫자 변수나 매개변수가 유효한 범위를 벗어났음을 나타내는 오류 인스턴스를 생성한다.
  - [`ReferenceError`](https://developer.mozilla.org/ko/docs/Web/JavaScript/Reference/Global_Objects/ReferenceError) : 잘못된 참조를 했음을 나타내는 오류 인스턴스를 생성한다.
  - [`SyntaxError`](https://developer.mozilla.org/ko/docs/Web/JavaScript/Reference/Global_Objects/SyntaxError) : `eval()` 코드를 분석하는 중 잘못된 구문을 만났음을 나타내는 오류 인스턴스를 생성한다.
  - [`TypeError`](https://developer.mozilla.org/ko/docs/Web/JavaScript/Reference/Global_Objects/TypeError) : 변수나 매개변수가 유효한 자료형이 아님을 나타내는 오류 인스턴스를 생성한다.
  - [`URIError`](https://developer.mozilla.org/ko/docs/Web/JavaScript/Reference/URIError) : `encodeURI()` 나 `decodeURI()` 함수에 부적절한 매개변수를 제공했을 때 발생하는 오류의 인스턴스를 생성한다.





### 예외 처리

- 에러가 발생하였을 때, `Error` 를 반환하고 `Error` 가 반환되었는지 `instanceof Error` 로 확인하여 예외를 처리하는 방법이 있다.

```javascript
function validateEmail(email) {
	return email.match(/@/)?
		email :
		new Error(`invalid email: ${email}`);
}

const email = 'jane@doe.com';

const validatedEmail = validateEmail(email);
if (validatedEmail instanceof Error) {
	console.log(`Error: ${validatedEmail.message}`);
} else {
	console.log(`Valid email: ${validatedEmail});
}

```

-  `try...catch` 문을 사용하여 예상치 못한 에러에서도 대처할 수 있다. 실행흐름은 `try` 문에서 에러 발생시 남은 작업을 중단하고 즉시 `catch` 문으로 이동한다. 예외가 나지 않을 경우, `catch` 문은 수행되지 않는다.

```javascript
const email = null;
try {
	const validatedEmail = validateEmail(email);
	if (validatedEmail instanceof Error) {
		console.log(`Error: ${validatedEmail.message}`);
	} else {
		console.log(`Valid email: ${validatedEmail});
	}
} catch (err) {
	console.log(`Error: ${err.message}`);
}
```

- `throw` 를 통해서 에러를 예상하고 일으킬 수 있다. `throw ` 를 호출하면 현재 함수는 즉시 실행을 멈춘다.

```javascript
function billPay(amount, payee, account) {
	if(amount > account.balance)
		throw new Error('insufficient funds');
	account.transfer(payee, amount);
}
```





### 예외 처리와 호출 스택

- 자바스크립트는 함수를 호출하는 과정을 모두 추적하는데, 이때, 완료되지 않는 함수가 쌓이는 것을 `호출 스택` 이라고 부른다.
- 이때, 에러가 발생한다면 캐치될 때까지 호출 스택을 따라 올라간다.
- 이 에러를 캐치하지 않으면 프로그램은 종료되고 이러한 에러를 `처리하지 않는 예외` `캐치하지 않은 예외` 라고 부른다.
- 에러를 캐치하면 캐치한 `Error` 객체를 통해서 호출스택 정보를 얻을 수 있는데, 이는 디버깅에 유용하게 사용된다.

```javascript
function a() {
	console.log('a: calling b');
	b();
	console.log('a done');
}

function b() {
	console.log('b: calling c');
	c();
	console.log('b done');
}

function c() {
	console.log('c: throwing Error');
	throw new Error('c error');
	console.log('c done');
}

function d() {
	console.log('d: calling c');
	c();
	console.log('d done');
}

try {
	a();
} catch (err) {
	console.log(err.stack);
	/*
		a: calling b
		b: calling c
		c: throwing Error
		c@debugger eval code:13:1
		b@debugger eval code:8:4
		a@debugger eval code:3:4
		@debugger eval code:23:4
	*/
}

try {
	d();
} catch (err) {
	console.log(err.stack);
	/*
		d: calling c
		c: throwing Error
		c@debugger eval code:13:1
		d@debugger eval code:18:4
		@debugger eval code:29:4
	*/
}
```



### try...catch...finally

- `try` 문에서 예러가 발생할 경우, 작업해야 할 다른 코드를을 모두 중단하는데 이로 인해 자원을 해제할 기회가 사라질 수 있다.
- 에러가 일어나는 일어나지 않든 무조건 수행되는 `finally` 문을 사용하여 자원을 안전하게 해제하도록 한다.

```javascript
try {
	console.log('this is line is executed...');
	throw Error('whoops');
	console.log('this line is not...');
} catch (err) {
	console.log('there was an error');
} finally {
	console.log('...always executed');
	console.log('perform cleanup here');
}
```

